2025-05-08 00:09:01,577 - INFO - === Начало процесса обновления данных ===
2025-05-08 00:09:01,577 - INFO - === Проверка базы данных ===
2025-05-08 00:09:01,577 - INFO - === Проверка целостности базы данных ===
2025-05-08 00:09:01,577 - INFO - Запуск скрипта check_db.py...
2025-05-08 00:09:01,610 - ERROR - Ошибка при выполнении скрипта check_db.py:
Traceback (most recent call last):
  File "/Users/golnev/Downloads/GJ/мерч/check_db.py", line 47, in <module>
    check_database() 
  File "/Users/golnev/Downloads/GJ/мерч/check_db.py", line 28, in check_database
    cursor.execute("SELECT * FROM category_weights")
sqlite3.OperationalError: no such table: category_weights

2025-05-08 00:09:01,611 - ERROR - Ошибка при запуске скрипта check_db.py: Скрипт check_db.py завершился с ошибкой
2025-05-08 00:09:01,611 - ERROR - Ошибка при проверке базы данных: Скрипт check_db.py завершился с ошибкой
2025-05-08 00:09:01,611 - ERROR - Критическая ошибка в процессе обновления данных: Скрипт check_db.py завершился с ошибкой
